Workbook

Sheet Ground Truth
A1: case_id | B1: dataset | C1: task_id | D1: task_name | E1: source_tables | F1: key_fields | G1: gold_available | H1: expected_status
A2: 1 | B2: UCI | C2: S-B01 | D2: Performance overview | E2: enrollment, assessment_result, assessment | F2: avg_score [FE], pass_rate [FE], performance_trend [FE], final_outcome | G2: YES | H2: executable
A3: 2 | B3: UCI | C3: S-B02 | D3: Risk status card | E3: enrollment, assessment_result, assessment, engagement | F3: at_risk_score [FE], at_risk_label [FE]; punctuality_rate [FE cross] (OULAD: submission_day/due_day; UCI: 1−absences_rate) | G3: YES | H3: executable
A4: 3 | B4: UCI | C4: S-B03 | D4: Engagement summary | E4: enrollment, engagement | F4: total_engagement_count [FE], active_days [FE], engagement_score [FE], class_avg_engagement_score [FE], study_effort_level [FE] | G4: NO | H4: insufficient_data
A5: 4 | B5: UCI | C5: S-T01 | D5: Score trend analysis | E5: assessment_result, assessment | F5: score_normalized, assessment_order, week_of_class, assessment_type; performance_trend [FE cross] | G5: YES | H5: executable
A6: 5 | B6: UCI | C6: S-T02 | D6: Competency gap analysis | E6: assessment_result, assessment | F6: competency_tag, score_normalized, pass_flag, assessment_type | G6: YES | H6: executable
A7: 6 | B7: UCI | C7: S-T03 | D7: Peer comparison | E7: enrollment, assessment_result, assessment, engagement | F7: avg_score [FE cross], engagement_score [FE cross], pass_rate [FE cross], performance_trend [FE cross] | G7: YES | H7: executable
A8: 7 | B8: UCI | C8: S-T04 | D8: At-risk self-check | E8: enrollment, assessment_result, assessment, engagement | F8: at_risk_score [FE cross], at_risk_label [FE cross], avg_score [FE cross], engagement_score [FE cross], punctuality_rate [FE cross], performance_trend [FE cross], previous_attempt_count | G8: YES | H8: executable
A9: 8 | B9: UCI | C9: S-T05 | D9: Weekly engagement trend | E9: engagement [OULAD only] | F9: week_number, engagement_count; early_warning_week [FE cross], weekly_engagement_drop [FE cross] | G9: NO | H9: insufficient_data
A10: 9 | B10: UCI | C10: S-T06 | D10: Study consistency check | E10: enrollment, engagement [OULAD only] | F10: week_number, engagement_count; consistency_level [FE cross] | G10: NO | H10: insufficient_data
A11: 10 | B11: UCI | C11: S-T07 | D11: Absence / inactivity impact | E11: enrollment, assessment_result, assessment | F11: absences [enrollment, UCI only]; score_normalized, pass_flag [assessment_result] | G11: YES | H11: executable
A12: 11 | B12: UCI | C12: S-T08 | D12: Assessment lateness impact | E12: assessment_result, assessment [OULAD only] | F12: submission_delay_days, score_normalized, assessment_type; submission_delay_avg [FE cross], punctuality_rate [FE cross] | G12: NO | H12: partial
... A105: 104 | B105: OULAD | C105: A-G16 | D105: Admin action recommendation | E105: enrollment, assessment_result, assessment, engagement | F105: [AI_SYNTHESIS] low_engagement_count, high_risk_count, hardest_assessment, best_resource_type, total_students | G105: YES | H105: executable

Sheet Machine Results
A1: case_id | B1: dataset | C1: batch_id | D1: class_id | E1: task_id | F1: task_name | G1: machine_available | H1: machine_status | I1: machine_reason | J1: structural | K1: semantic | L1: analytical | M1: data_sufficiency | N1: missing_required_capabilities | O1: missing_any_capabilities | P1: confidence | Q1: confidence_reason | R1: gold_available | S1: expected_status | T1: status_correct | U1: gold_reason | V1: correct | W1: error_type
A2: 1 | B2: UCI | C2: SAMPLE_UCI_POR | D2: SAMPLE_UCI_POR_CLASS | E2: S-B01 | F2: Performance overview | G2: YES | H2: executable | J2: pass | K2: pass | L2: pass | M2: pass | P2: HIGH | Q2: 649 students × 3 assessments across 3 weeks - strong statistical basic | R2: =IFERROR(INDEX('Ground Truth'!$G$2:$G$105,MATCH(A2,'Ground Truth'!$A$2:$A$105,0)),"") -> YES | S2: =IFERROR(INDEX('Ground Truth'!$H$2:$H$105,MATCH(A2,'Ground Truth'!$A$2:$A$105,0)),"") -> executable | T2: =IF(S2="","",--(S2=H2)) -> 1 | U2: =IF(R2="","","Compared with user-reviewed Ground Truth") -> Compared with user-reviewed Ground Truth | V2: =IF(R2="","",--(R2=G2)) -> 1 | W2: =IF(R2="","",IF(AND(R2="YES",G2="YES"),"TP",IF(AND(R2="NO",G2="NO"),"TN",IF(AND(R2="NO",G2="YES"),"FP",IF(AND(R2="YES",G2="NO"),"FN","CHECK"))))) -> TP
A3: 2 | B3: UCI | C3: SAMPLE_UCI_POR | D3: SAMPLE_UCI_POR_CLASS | E3: S-B02 | F3: Risk status card | G3: YES | H3: executable | J3: pass | K3: pass | L3: pass | M3: pass | P3: HIGH | Q3: 649 students × 3 assessments across 3 weeks - strong statistical basic | R3: =IFERROR(INDEX('Ground Truth'!$G$2:$G$105,MATCH(A3,'Ground Truth'!$A$2:$A$105,0)),"") -> YES | S3: =IFERROR(INDEX('Ground Truth'!$H$2:$H$105,MATCH(A3,'Ground Truth'!$A$2:$A$105,0)),"") -> executable | T3: =IF(S3="","",--(S3=H3)) -> 1 | U3: =IF(R3="","","Compared with user-reviewed Ground Truth") -> Compared with user-reviewed Ground Truth | V3: =IF(R3="","",--(R3=G3)) -> 1 | W3: =IF(R3="","",IF(AND(R3="YES",G3="YES"),"TP",IF(AND(R3="NO",G3="NO"),"TN",IF(AND(R3="NO",G3="YES"),"FP",IF(AND(R3="YES",G3="NO"),"FN","CHECK"))))) -> TP
A4: 3 | B4: UCI | C4: SAMPLE_UCI_POR | D4: SAMPLE_UCI_POR_CLASS | E4: S-B03 | F4: Engagement summary | G4: NO | H4: insufficient_data | I4: Required capability missing: engagement_tracking | J4: pass | K4: fail | L4: pass | M4: fail | N4: engagement_tracking | P4: LOW | Q4: No positive engagement activity found (0 engagement rows). | R4: =IFERROR(INDEX('Ground Truth'!$G$2:$G$105,MATCH(A4,'Ground Truth'!$A$2:$A$105,0)),"") -> NO | S4: =IFERROR(INDEX('Ground Truth'!$H$2:$H$105,MATCH(A4,'Ground Truth'!$A$2:$A$105,0)),"") -> insufficient_data | T4: =IF(S4="","",--(S4=H4)) -> 1 | U4: =IF(R4="","","Compared with user-reviewed Ground Truth") -> Compared with user-reviewed Ground Truth | V4: =IF(R4="","",--(R4=G4)) -> 1 | W4: =IF(R4="","",IF(AND(R4="YES",G4="YES"),"TP",IF(AND(R4="NO",G4="NO"),"TN",IF(AND(R4="NO",G4="YES"),"FP",IF(AND(R4="YES",G4="NO"),"FN","CHECK"))))) -> TN
A5: 4 | B5: UCI | C5: SAMPLE_UCI_POR | D5: SAMPLE_UCI_POR_CLASS | E5: S-T01 | F5: Score trend analysis | G5: YES | H5: executable | J5: pass | K5: pass | L5: pass | M5: pass | P5: HIGH | Q5: 649 students × 3 assessments across 3 weeks - strong statistical basic | R5: =IFERROR(INDEX('Ground Truth'!$G$2:$G$105,MATCH(A5,'Ground Truth'!$A$2:$A$105,0)),"") -> YES | S5: =IFERROR(INDEX('Ground Truth'!$H$2:$H$105,MATCH(A5,'Ground Truth'!$A$2:$A$105,0)),"") -> executable | T5: =IF(S5="","",--(S5=H5)) -> 1 | U5: =IF(R5="","","Compared with user-reviewed Ground Truth") -> Compared with user-reviewed Ground Truth | V5: =IF(R5="","",--(R5=G5)) -> 1 | W5: =IF(R5="","",IF(AND(R5="YES",G5="YES"),"TP",IF(AND(R5="NO",G5="NO"),"TN",IF(AND(R5="NO",G5="YES"),"FP",IF(AND(R5="YES",G5="NO"),"FN","CHECK"))))) -> TP
A6: 5 | B6: UCI | C6: SAMPLE_UCI_POR | D6: SAMPLE_UCI_POR_CLASS | E6: S-T02 | F6: Competency gap analysis | G6: YES | H6: executable | J6: pass | K6: pass | L6: pass | M6: pass | P6: HIGH | Q6: 649 students × 3 assessments across 3 weeks - strong statistical basic | R6: =IFERROR(INDEX('Ground Truth'!$G$2:$G$105,MATCH(A6,'Ground Truth'!$A$2:$A$105,0)),"") -> YES | S6: =IFERROR(INDEX('Ground Truth'!$H$2:$H$105,MATCH(A6,'Ground Truth'!$A$2:$A$105,0)),"") -> executable | T6: =IF(S6="","",--(S6=H6)) -> 1 | U6: =IF(R6="","","Compared with user-reviewed Ground Truth") -> Compared with user-reviewed Ground Truth | V6: =IF(R6="","",--(R6=G6)) -> 1 | W6: =IF(R6="","",IF(AND(R6="YES",G6="YES"),"TP",IF(AND(R6="NO",G6="NO"),"TN",IF(AND(R6="NO",G6="YES"),"FP",IF(AND(R6="YES",G6="NO"),"FN","CHECK"))))) -> TP
A7: 6 | B7: UCI | C7: SAMPLE_UCI_POR | D7: SAMPLE_UCI_POR_CLASS | E7: S-T03 | F7: Peer comparison | G7: YES | H7: executable | J7: pass | K7: pass | L7: pass | M7: pass | P7: HIGH | Q7: 649 students × 3 assessments across 3 weeks - strong statistical basic | R7: =IFERROR(INDEX('Ground Truth'!$G$2:$G$105,MATCH(A7,'Ground Truth'!$A$2:$A$105,0)),"") -> YES | S7: =IFERROR(INDEX('Ground Truth'!$H$2:$H$105,MATCH(A7,'Ground Truth'!$A$2:$A$105,0)),"") -> executable | T7: =IF(S7="","",--(S7=H7)) -> 1 | U7: =IF(R7="","","Compared with user-reviewed Ground Truth") -> Compared with user-reviewed Ground Truth | V7: =IF(R7="","",--(R7=G7)) -> 1 | W7: =IF(R7="","",IF(AND(R7="YES",G7="YES"),"TP",IF(AND(R7="NO",G7="NO"),"TN",IF(AND(R7="NO",G7="YES"),"FP",IF(AND(R7="YES",G7="NO"),"FN","CHECK"))))) -> TP
A8: 7 | B8: UCI | C8: SAMPLE_UCI_POR | D8: SAMPLE_UCI_POR_CLASS | E8: S-T04 | F8: At-risk self-check | G8: YES | H8: executable | J8: pass | K8: pass | L8: pass | M8: pass | P8: HIGH | Q8: 649 students × 3 assessments across 3 weeks - strong statistical basic | R8: =IFERROR(INDEX('Ground Truth'!$G$2:$G$105,MATCH(A8,'Ground Truth'!$A$2:$A$105,0)),"") -> YES | S8: =IFERROR(INDEX('Ground Truth'!$H$2:$H$105,MATCH(A8,'Ground Truth'!$A$2:$A$105,0)),"") -> executable | T8: =IF(S8="","",--(S8=H8)) -> 1 | U8: =IF(R8="","","Compared with user-reviewed Ground Truth") -> Compared with user-reviewed Ground Truth | V8: =IF(R8="","",--(R8=G8)) -> 1 | W8: =IF(R8="","",IF(AND(R8="YES",G8="YES"),"TP",IF(AND(R8="NO",G8="NO"),"TN",IF(AND(R8="NO",G8="YES"),"FP",IF(AND(R8="YES",G8="NO"),"FN","CHECK"))))) -> TP
A9: 8 | B9: UCI | C9: SAMPLE_UCI_POR | D9: SAMPLE_UCI_POR_CLASS | E9: S-T05 | F9: Weekly engagement trend | G9: NO | H9: insufficient_data | I9: Required capability missing: engagement_tracking | J9: pass | K9: fail | L9: pass | M9: fail | N9: engagement_tracking; temporal_activity | P9: LOW | Q9: No positive engagement activity found (0 engagement rows). | R9: =IFERROR(INDEX('Ground Truth'!$G$2:$G$105,MATCH(A9,'Ground Truth'!$A$2:$A$105,0)),"") -> NO | S9: =IFERROR(INDEX('Ground Truth'!$H$2:$H$105,MATCH(A9,'Ground Truth'!$A$2:$A$105,0)),"") -> insufficient_data | T9: =IF(S9="","",--(S9=H9)) -> 1 | U9: =IF(R9="","","Compared with user-reviewed Ground Truth") -> Compared with user-reviewed Ground Truth | V9: =IF(R9="","",--(R9=G9)) -> 1 | W9: =IF(R9="","",IF(AND(R9="YES",G9="YES"),"TP",IF(AND(R9="NO",G9="NO"),"TN",IF(AND(R9="NO",G9="YES"),"FP",IF(AND(R9="YES",G9="NO"),"FN","CHECK"))))) -> TN
A10: 9 | B10: UCI | C10: SAMPLE_UCI_POR | D10: SAMPLE_UCI_POR_CLASS | E10: S-T06 | F10: Study consistency check | G10: NO | H10: insufficient_data | I10: Task depends on OULAD week-level engagement patterns and outcome labels. | J10: pass | K10: fail | L10: pass | M10: fail | N10: engagement_tracking; temporal_activity | P10: LOW | Q10: No positive engagement activity found (0 engagement rows). | R10: =IFERROR(INDEX('Ground Truth'!$G$2:$G$105,MATCH(A10,'Ground Truth'!$A$2:$A$105,0)),"") -> NO | S10: =IFERROR(INDEX('Ground Truth'!$H$2:$H$105,MATCH(A10,'Ground Truth'!$A$2:$A$105,0)),"") -> insufficient_data | T10: =IF(S10="","",--(S10=H10)) -> 1 | U10: =IF(R10="","","Compared with user-reviewed Ground Truth") -> Compared with user-reviewed Ground Truth | V10: =IF(R10="","",--(R10=G10)) -> 1 | W10: =IF(R10="","",IF(AND(R10="YES",G10="YES"),"TP",IF(AND(R10="NO",G10="NO"),"TN",IF(AND(R10="NO",G10="YES"),"FP",IF(AND(R10="YES",G10="NO"),"FN","CHECK"))))) -> TN
A11: 10 | B11: UCI | C11: SAMPLE_UCI_POR | D11: SAMPLE_UCI_POR_CLASS | E11: S-T07 | F11: Absence / inactivity impact | G11: YES | H11: executable | J11: pass | K11: pass | L11: pass | M11: pass | P11: HIGH | Q11: 649 students × 3 assessments across 3 weeks - strong statistical basic | R11: =IFERROR(INDEX('Ground Truth'!$G$2:$G$105,MATCH(A11,'Ground Truth'!$A$2:$A$105,0)),"") -> YES | S11: =IFERROR(INDEX('Ground Truth'!$H$2:$H$105,MATCH(A11,'Ground Truth'!$A$2:$A$105,0)),"") -> executable | T11: =IF(S11="","",--(S11=H11)) -> 1 | U11: =IF(R11="","","Compared with user-reviewed Ground Truth") -> Compared with user-reviewed Ground Truth | V11: =IF(R11="","",--(R11=G11)) -> 1 | W11: =IF(R11="","",IF(AND(R11="YES",G11="YES"),"TP",IF(AND(R11="NO",G11="NO"),"TN",IF(AND(R11="NO",G11="YES"),"FP",IF(AND(R11="YES",G11="NO"),"FN","CHECK"))))) -> TP
A12: 11 | B12: UCI | C12: SAMPLE_UCI_POR | D12: SAMPLE_UCI_POR_CLASS | E12: S-T08 | F12: Assessment lateness impact | G12: NO | H12: partial | I12: Required capability missing: submission_timestamps | J12: pass | K12: fail | L12: pass | M12: pass | N12: submission_timestamps | P12: HIGH | Q12: 649 students × 3 assessments across 3 weeks - strong statistical basic | R12: =IFERROR(INDEX('Ground Truth'!$G$2:$G$105,MATCH(A12,'Ground Truth'!$A$2:$A$105,0)),"") -> NO | S12: =IFERROR(INDEX('Ground Truth'!$H$2:$H$105,MATCH(A12,'Ground Truth'!$A$2:$A$105,0)),"") -> partial | T12: =IF(S12="","",--(S12=H12)) -> 1 | U12: =IF(R12="","","Compared with user-reviewed Ground Truth") -> Compared with user-reviewed Ground Truth | V12: =IF(R12="","",--(R12=G12)) -> 1 | W12: =IF(R12="","",IF(AND(R12="YES",G12="YES"),"TP",IF(AND(R12="NO",G12="NO"),"TN",IF(AND(R12="NO",G12="YES"),"FP",IF(AND(R12="YES",G12="NO"),"FN","CHECK"))))) -> TN
A13: 12 | B13: UCI | C13: SAMPLE_UCI_POR | D13: SAMPLE_UCI_POR_CLASS | E13: S-T09 | F13: Lifestyle risk vs performance | G13: YES | H13: executable | J13: pass | K13: pass | L13: pass | M13: pass | P13: HIGH | Q13: 649 students × 3 assessments across 3 weeks - strong statistical basic | R13: =IFERROR(INDEX('Ground Truth'!$G$2:$G$105,MATCH(A13,'Ground Truth'!$A$2:$A$105,0)),"") -> YES | S13: =IFERROR(INDEX('Ground Truth'!$H$2:$H$105,MATCH(A13,'Ground Truth'!$A$2:$A$105,0)),"") -> executable | T13: =IF(S13="","",--(S13=H13)) -> 1 | U13: =IF(R13="","","Compared with user-reviewed Ground Truth") -> Compared with user-reviewed Ground Truth | V13: =IF(R13="","",--(R13=G13)) -> 1 | W13: =IF(R13="","",IF(AND(R13="YES",G13="YES"),"TP",IF(AND(R13="NO",G13="NO"),"TN",IF(AND(R13="NO",G13="YES"),"FP",IF(AND(R13="YES",G13="NO"),"FN","CHECK"))))) -> TP
A14: 13 | B14: UCI | C14: SAMPLE_UCI_POR | D14: SAMPLE_UCI_POR_CLASS | E14: S-T10 | F14: Resource engagement breakdown | G14: NO | H14: insufficient_data | I14: Required capability missing: engagement_tracking | J14: pass | K14: fail | L14: pass | M14: fail | N14: engagement_tracking; resource_clickstream | P14: LOW | Q14: No positive engagement activity found (0 engagement rows). | R14: =IFERROR(INDEX('Ground Truth'!$G$2:$G$105,MATCH(A14,'Ground Truth'!$A$2:$A$105,0)),"") -> NO | S14: =IFERROR(INDEX('Ground Truth'!$H$2:$H$105,MATCH(A14,'Ground Truth'!$A$2:$A$105,0)),"") -> insufficient_data | T14: =IF(S14="","",--(S14=H14)) -> 1 | U14: =IF(R14="","","Compared with user-reviewed Ground Truth") -> Compared with user-reviewed Ground Truth | V14: =IF(R14="","",--(R14=G14)) -> 1 | W14: =IF(R14="","",IF(AND(R14="YES",G14="YES"),"TP",IF(AND(R14="NO",G14="NO"),"TN",IF(AND(R14="NO",G14="YES"),"FP",IF(AND(R14="YES",G14="NO"),"FN","CHECK"))))) -> TN
A15: 14 | B15: UCI | C15: SAMPLE_UCI_POR | D15: SAMPLE_UCI_POR_CLASS | E15: S-T11 | F15: Registration timing vs performance | G15: NO | H15: partial | I15: Required capability missing: registration_timing | J15: pass | K15: fail | L15: pass | M15: pass | N15: registration_timing | P15: HIGH | Q15: 649 students × 3 assessments across 3 weeks - strong statistical basic | R15: =IFERROR(INDEX('Ground Truth'!$G$2:$G$105,MATCH(A15,'Ground Truth'!$A$2:$A$105,0)),"") -> NO | S15: =IFERROR(INDEX('Ground Truth'!$H$2:$H$105,MATCH(A15,'Ground Truth'!$A$2:$A$105,0)),"") -> partial | T15: =IF(S15="","",--(S15=H15)) -> 1 | U15: =IF(R15="","","Compared with user-reviewed Ground Truth") -> Compared with user-reviewed Ground Truth | V15: =IF(R15="","",--(R15=G15)) -> 1 | W15: =IF(R15="","",IF(AND(R15="YES",G15="YES"),"TP",IF(AND(R15="NO",G15="NO"),"TN",IF(AND(R15="NO",G15="YES"),"FP",IF(AND(R15="YES",G15="NO"),"FN","CHECK"))))) -> TN
A16: 15 | B16: UCI | C16: SAMPLE_UCI_POR | D16: SAMPLE_UCI_POR_CLASS | E16: S-T12 | F16: Procrastination analysis | G16: NO | H16: partial | I16: Required capability missing: submission_timestamps | J16: pass | K16: fail | L16: pass | M16: pass | N16: submission_timestamps | P16: HIGH | Q16: 649 students × 3 assessments across 3 weeks - strong statistical basic | R16: =IFERROR(INDEX('Ground Truth'!$G$2:$G$105,MATCH(A16,'Ground Truth'!$A$2:$A$105,0)),"") -> NO | S16: =IFERROR(INDEX('Ground Truth'!$H$2:$H$105,MATCH(A16,'Ground Truth'!$A$2:$A$105,0)),"") -> partial | T16: =IF(S16="","",--(S16=H16)) -> 1 | U16: =IF(R16="","","Compared with user-reviewed Ground Truth") -> Compared with user-reviewed Ground Truth | V16: =IF(R16="","",--(R16=G16)) -> 1 | W16: =IF(R16="","",IF(AND(R16="YES",G16="YES"),"TP",IF(AND(R16="NO",G16="NO"),"TN",IF(AND(R16="NO",G16="YES"),"FP",IF(AND(R16="YES",G16="NO"),"FN","CHECK"))))) -> TN
A17: 16 | B17: UCI | C17: SAMPLE_UCI_POR | D17: SAMPLE_UCI_POR_CLASS | E17: S-T13 | F17: Action plan generation | G17: YES | H17: executable | J17: pass | K17: pass | L17: pass | M17: pass | P17: HIGH | Q17: 649 students × 3 assessments across 3 weeks - strong statistical basic | R17: =IFERROR(INDEX('Ground Truth'!$G$2:$G$105,MATCH(A17,'Ground Truth'!$A$2:$A$105,0)),"") -> YES | S17: =IFERROR(INDEX('Ground Truth'!$H$2:$H$105,MATCH(A17,'Ground Truth'!$A$2:$A$105,0)),"") -> executable | T17: =IF(S17="","",--(S17=H17)) -> 1 | U17: =IF(R17="","","Compared with user-reviewed Ground Truth") -> Compared with user-reviewed Ground Truth | V17: =IF(R17="","",--(R17=G17)) -> 1 | W17: =IF(R17="","",IF(AND(R17="YES",G17="YES"),"TP",IF(AND(R17="NO",G17="NO"),"TN",IF(AND(R17="NO",G17="YES"),"FP",IF(AND(R17="YES",G17="NO"),"FN","CHECK"))))) -> TP
A18: 17 | B18: UCI | C18: SAMPLE_UCI_POR | D18: SAMPLE_UCI_POR_CLASS | E18: S-T14 | F18: Social balance vs performance | G18: YES | H18: executable | J18: pass | K18: pass | L18: pass | M18: pass | P18: HIGH | Q18: 649 students × 3 assessments across 3 weeks - strong statistical basic | R18: =IFERROR(INDEX('Ground Truth'!$G$2:$G$105,MATCH(A18,'Ground Truth'!$A$2:$A$105,0)),"") -> YES | S18: =IFERROR(INDEX('Ground Truth'!$H$2:$H$105,MATCH(A18,'Ground Truth'!$A$2:$A$105,0)),"") -> executable | T18: =IF(S18="","",--(S18=H18)) -> 1 | U18: =IF(R18="","","Compared with user-reviewed Ground Truth") -> Compared with user-reviewed Ground Truth | V18: =IF(R18="","",--(R18=G18)) -> 1 | W18: =IF(R18="","",IF(AND(R18="YES",G18="YES"),"TP",IF(AND(R18="NO",G18="NO"),"TN",IF(AND(R18="NO",G18="YES"),"FP",IF(AND(R18="YES",G18="NO"),"FN","CHECK"))))) -> TP
A19: 18 | B19: UCI | C19: SAMPLE_UCI_POR | D19: SAMPLE_UCI_POR_CLASS | E19: S-T15 | F19: Family context vs performance | G19: YES | H19: executable | J19: pass | K19: pass | L19: pass | M19: pass | P19: HIGH | Q19: 649 students × 3 assessments across 3 weeks - strong statistical basic | R19: =IFERROR(INDEX('Ground Truth'!$G$2:$G$105,MATCH(A19,'Ground Truth'!$A$2:$A$105,0)),"") -> YES | S19: =IFERROR(INDEX('Ground Truth'!$H$2:$H$105,MATCH(A19,'Ground Truth'!$A$2:$A$105,0)),"") -> executable | T19: =IF(S19="","",--(S19=H19)) -> 1 | U19: =IF(R19="","","Compared with user-reviewed Ground Truth") -> Compared with user-reviewed Ground Truth | V19: =IF(R19="","",--(R19=G19)) -> 1 | W19: =IF(R19="","",IF(AND(R19="YES",G19="YES"),"TP",IF(AND(R19="NO",G19="NO"),"TN",IF(AND(R19="NO",G19="YES"),"FP",IF(AND(R19="YES",G19="NO"),"FN","CHECK"))))) -> TP
A20: 19 | B20: UCI | C20: SAMPLE_UCI_POR | D20: SAMPLE_UCI_POR_CLASS | E20: A-B01 | F20: Overall performance distribution | G20: YES | H20: executable | J20: pass | K20: pass | L20: pass | M20: pass | P20: HIGH | Q20: 649 students × 3 assessments across 3 weeks - strong statistical basic | R20: =IFERROR(INDEX('Ground Truth'!$G$2:$G$105,MATCH(A20,'Ground Truth'!$A$2:$A$105,0)),"") -> YES | S20: =IFERROR(INDEX('Ground Truth'!$H$2:$H$105,MATCH(A20,'Ground Truth'!$A$2:$A$105,0)),"") -> executable | T20: =IF(S20="","",--(S20=H20)) -> 1 | U20: =IF(R20="","","Compared with user-reviewed Ground Truth") -> Compared with user-reviewed Ground Truth | V20: =IF(R20="","",--(R20=G20)) -> 1 | W20: =IF(R20="","",IF(AND(R20="YES",G20="YES"),"TP",IF(AND(R20="NO",G20="NO"),"TN",IF(AND(R20="NO",G20="YES"),"FP",IF(AND(R20="YES",G20="NO"),"FN","CHECK"))))) -> TP
A21: 20 | B21: UCI | C21: SAMPLE_UCI_POR | D21: SAMPLE_UCI_POR_CLASS | E21: A-B02 | F21: Completion / outcome summary | G21: YES | H21: executable | J21: pass | K21: pass | L21: pass | M21: pass | P21: HIGH | Q21: 649 students × 3 assessments across 3 weeks - strong statistical basic | R21: =IFERROR(INDEX('Ground Truth'!$G$2:$G$105,MATCH(A21,'Ground Truth'!$A$2:$A$105,0)),"") -> YES | S21: =IFERROR(INDEX('Ground Truth'!$H$2:$H$105,MATCH(A21,'Ground Truth'!$A$2:$A$105,0)),"") -> executable | T21: =IF(S21="","",--(S21=H21)) -> 1 | U21: =IF(R21="","","Compared with user-reviewed Ground Truth") -> Compared with user-reviewed Ground Truth | V21: =IF(R21="","",--(R21=G21)) -> 1 | W21: =IF(R21="","",IF(AND(R21="YES",G21="YES"),"TP",IF(AND(R21="NO",G21="NO"),"TN",IF(AND(R21="NO",G21="YES"),"FP",IF(AND(R21="YES",G21="NO"),"FN","CHECK"))))) -> TP
A22: 21 | B22: UCI | C22: SAMPLE_UCI_POR | D22: SAMPLE_UCI_POR_CLASS | E22: A-B03 | F22: Engagement distribution | G22: NO | H22: insufficient_data | I22: Required capability missing: engagement_tracking | J22: pass | K22: fail | L22: pass | M22: fail | N22: engagement_tracking | P22: LOW | Q22: No positive engagement activity found (0 engagement rows). | R22: =IFERROR(INDEX('Ground Truth'!$G$2:$G$105,MATCH(A22,'Ground Truth'!$A$2:$A$105,0)),"") -> NO | S22: =IFERROR(INDEX('Ground Truth'!$H$2:$H$105,MATCH(A22,'Ground Truth'!$A$2:$A$105,0)),"") -> insufficient_data | T22: =IF(S22="","",--(S22=H22)) -> 1 | U22: =IF(R22="","","Compared with user-reviewed Ground Truth") -> Compared with user-reviewed Ground Truth | V22: =IF(R22="","",--(R22=G22)) -> 1 | W22: =IF(R22="","",IF(AND(R22="YES",G22="YES"),"TP",IF(AND(R22="NO",G22="NO"),"TN",IF(AND(R22="NO",G22="YES"),"FP",IF(AND(R22="YES",G22="NO"),"FN","CHECK"))))) -> TN
A23: 22 | B23: UCI | C23: SAMPLE_UCI_POR | D23: SAMPLE_UCI_POR_CLASS | E23: A-B04 | F23: At-risk overview | G23: NO | H23: insufficient_data | I23: Task depends on OULAD week-level engagement patterns and outcome labels. | J23: pass | K23: fail | L23: pass | M23: fail | N23: engagement_tracking; temporal_activity | P23: LOW | Q23: No positive engagement activity found (0 engagement rows). | R23: =IFERROR(INDEX('Ground Truth'!$G$2:$G$105,MATCH(A23,'Ground Truth'!$A$2:$A$105,0)),"") -> NO | S23: =IFERROR(INDEX('Ground Truth'!$H$2:$H$105,MATCH(A23,'Ground Truth'!$A$2:$A$105,0)),"") -> insufficient_data | T23: =IF(S23="","",--(S23=H23)) -> 1 | U23: =IF(R23="","","Compared with user-reviewed Ground Truth") -> Compared with user-reviewed Ground Truth | V23: =IF(R23="","",--(R23=G23)) -> 1 | W23: =IF(R23="","",IF(AND(R23="YES",G23="YES"),"TP",IF(AND(R23="NO",G23="NO"),"TN",IF(AND(R23="NO",G23="YES"),"FP",IF(AND(R23="YES",G23="NO"),"FN","CHECK"))))) -> TN
A24: 23 | B24: UCI | C24: SAMPLE_UCI_POR | D24: SAMPLE_UCI_POR_CLASS | E24: A-S01 | F24: Student full profile snapshot | G24: NO | H24: insufficient_data | I24: Required capability missing: engagement_tracking | J24: pass | K24: fail | L24: pass | M24: fail | N24: engagement_tracking | P24: LOW | Q24: No positive engagement activity found (0 engagement rows). | R24: =IFERROR(INDEX('Ground Truth'!$G$2:$G$105,MATCH(A24,'Ground Truth'!$A$2:$A$105,0)),"") -> NO | S24: =IFERROR(INDEX('Ground Truth'!$H$2:$H$105,MATCH(A24,'Ground Truth'!$A$2:$A$105,0)),"") -> insufficient_data | T24: =IF(S24="","",--(S24=H24)) -> 1 | U24: =IF(R24="","","Compared with user-reviewed Ground Truth") -> Compared with user-reviewed Ground Truth | V24: =IF(R24="","",--(R24=G24)) -> 1 | W24: =IF(R24="","",IF(AND(R24="YES",G24="YES"),"TP",IF(AND(R24="NO",G24="NO"),"TN",IF(AND(R24="NO",G24="YES"),"FP",IF(AND(R24="YES",G24="NO"),"FN","CHECK"))))) -> TN
A25: 24 | B25: UCI | C25: SAMPLE_UCI_POR | D25: SAMPLE_UCI_POR_CLASS | E25: A-S02 | F25: Student score trend | G25: YES | H25: executable | J25: pass | K25: pass | L25: pass | M25: pass | P25: HIGH | Q25: 649 students × 3 assessments across 3 weeks - strong statistical basic | R25: =IFERROR(INDEX('Ground Truth'!$G$2:$G$105,MATCH(A25,'Ground Truth'!$A$2:$A$105,0)),"") -> YES | S25: =IFERROR(INDEX('Ground Truth'!$H$2:$H$105,MATCH(A25,'Ground Truth'!$A$2:$A$105,0)),"") -> executable | T25: =IF(S25="","",--(S25=H25)) -> 1 | U25: =IF(R25="","","Compared with user-reviewed Ground Truth") -> Compared with user-reviewed Ground Truth | V25: =IF(R25="","",--(R25=G25)) -> 1 | W25: =IF(R25="","",IF(AND(R25="YES",G25="YES"),"TP",IF(AND(R25="NO",G25="NO"),"TN",IF(AND(R25="NO",G25="YES"),"FP",IF(AND(R25="YES",G25="NO"),"FN","CHECK"))))) -> TP
A26: 25 | B26: UCI | C26: SAMPLE_UCI_POR | D26: SAMPLE_UCI_POR_CLASS | E26: A-S03 | F26: Student engagement trajectory | G26: NO | H26: insufficient_data | I26: Required capability missing: engagement_tracking | J26: pass | K26: fail | L26: pass | M26: fail | N26: engagement_tracking; temporal_activity | P26: LOW | Q26: No positive engagement activity found (0 engagement rows). | R26: =IFERROR(INDEX('Ground Truth'!$G$2:$G$105,MATCH(A26,'Ground Truth'!$A$2:$A$105,0)),"") -> NO | S26: =IFERROR(INDEX('Ground Truth'!$H$2:$H$105,MATCH(A26,'Ground Truth'!$A$2:$A$105,0)),"") -> insufficient_data | T26: =IF(S26="","",--(S26=H26)) -> 1 | U26: =IF(R26="","","Compared with user-reviewed Ground Truth") -> Compared with user-reviewed Ground Truth | V26: =IF(R26="","",--(R26=G26)) -> 1 | W26: =IF(R26="","",IF(AND(R26="YES",G26="YES"),"TP",IF(AND(R26="NO",G26="NO"),"TN",IF(AND(R26="NO",G26="YES"),"FP",IF(AND(R26="YES",G26="NO"),"FN","CHECK"))))) -> TN
A27: 26 | B27: UCI | C27: SAMPLE_UCI_POR | D27: SAMPLE_UCI_POR_CLASS | E27: A-S04 | F27: Student risk flag breakdown | G27: YES | H27: executable | J27: pass | K27: pass | L27: pass | M27: pass | P27: HIGH | Q27: 649 students × 3 assessments across 3 weeks - strong statistical basic | R27: =IFERROR(INDEX('Ground Truth'!$G$2:$G$105,MATCH(A27,'Ground Truth'!$A$2:$A$105,0)),"") -> YES | S27: =IFERROR(INDEX('Ground Truth'!$H$2:$H$105,MATCH(A27,'Ground Truth'!$A$2:$A$105,0)),"") -> executable | T27: =IF(S27="","",--(S27=H27)) -> 1 | U27: =IF(R27="","","Compared with user-reviewed Ground Truth") -> Compared with user-reviewed Ground Truth | V27: =IF(R27="","",--(R27=G27)) -> 1 | W27: =IF(R27="","",IF(AND(R27="YES",G27="YES"),"TP",IF(AND(R27="NO",G27="NO"),"TN",IF(AND(R27="NO",G27="YES"),"FP",IF(AND(R27="YES",G27="NO"),"FN","CHECK"))))) -> TP
A28: 27 | B28: UCI | C28: SAMPLE_UCI_POR | D28: SAMPLE_UCI_POR_CLASS | E28: A-S05 | F28: Student competency gap | G28: YES | H28: executable | J28: pass | K28: pass | L28: pass | M28: pass | P28: HIGH | Q28: 649 students × 3 assessments across 3 weeks - strong statistical basic | R28: =IFERROR(INDEX('Ground Truth'!$G$2:$G$105,MATCH(A28,'Ground Truth'!$A$2:$A$105,0)),"") -> YES | S28: =IFERROR(INDEX('Ground Truth'!$H$2:$H$105,MATCH(A28,'Ground Truth'!$A$2:$A$105,0)),"") -> executable | T28: =IF(S28="","",--(S28=H28)) -> 1 | U28: =IF(R28="","","Compared with user-reviewed Ground Truth") -> Compared with user-reviewed Ground Truth | V28: =IF(R28="","",--(R28=G28)) -> 1 | W28: =IF(R28="","",IF(AND(R28="YES",G28="YES"),"TP",IF(AND(R28="NO",G28="NO"),"TN",IF(AND(R28="NO",G28="YES"),"FP",IF(AND(R28="YES",G28="NO"),"FN","CHECK"))))) -> TP
A29: 28 | B29: UCI | C29: SAMPLE_UCI_POR | D29: SAMPLE_UCI_POR_CLASS | E29: A-S06 | F29: Student submission & punctuality | G29: NO | H29: partial | I29: Required capability missing: submission_timestamps | J29: pass | K29: fail | L29: pass | M29: pass | N29: submission_timestamps | P29: HIGH | Q29: 649 students × 3 assessments across 3 weeks - strong statistical basic | R29: =IFERROR(INDEX('Ground Truth'!$G$2:$G$105,MATCH(A29,'Ground Truth'!$A$2:$A$105,0)),"") -> NO | S29: =IFERROR(INDEX('Ground Truth'!$H$2:$H$105,MATCH(A29,'Ground Truth'!$A$2:$A$105,0)),"") -> partial | T29: =IF(S29="","",--(S29=H29)) -> 1 | U29: =IF(R29="","","Compared with user-reviewed Ground Truth") -> Compared with user-reviewed Ground Truth | V29: =IF(R29="","",--(R29=G29)) -> 1 | W29: =IF(R29="","",IF(AND(R29="YES",G29="YES"),"TP",IF(AND(R29="NO",G29="NO"),"TN",IF(AND(R29="NO",G29="YES"),"FP",IF(AND(R29="YES",G29="NO"),"FN","CHECK"))))) -> TN
A30: 29 | B30: UCI | C30: SAMPLE_UCI_POR | D30: SAMPLE_UCI_POR_CLASS | E30: A-S07 | F30: Student background context | G30: YES | H30: executable | J30: pass | K30: pass | L30: pass | M30: pass | P30: HIGH | Q30: 649 students × 3 assessments across 3 weeks - strong statistical basic | R30: =IFERROR(INDEX('Ground Truth'!$G$2:$G$105,MATCH(A30,'Ground Truth'!$A$2:$A$105,0)),"") -> YES | S30: =IFERROR(INDEX('Ground Truth'!$H$2:$H$105,MATCH(A30,'Ground Truth'!$A$2:$A$105,0)),"") -> executable | T30: =IF(S30="","",--(S30=H30)) -> 1 | U30: =IF(R30="","","Compared with user-reviewed Ground Truth") -> Compared with user-reviewed Ground Truth | V30: =IF(R30="","",--(R30=G30)) -> 1 | W30: =IF(R30="","",IF(AND(R30="YES",G30="YES"),"TP",IF(AND(R30="NO",G30="NO"),"TN",IF(AND(R30="NO",G30="YES"),"FP",IF(AND(R30="YES",G30="NO"),"FN","CHECK"))))) -> TP
A31: 30 | B31: UCI | C31: SAMPLE_UCI_POR | D31: SAMPLE_UCI_POR_CLASS | E31: A-S08 | F31: Student intervention recommendation | G31: NO | H31: insufficient_data | I31: Task depends on OULAD engagement/online activity signals. | J31: pass | K31: fail | L31: pass | M31: fail | N31: engagement_tracking | P31: LOW | Q31: No positive engagement activity found (0 engagement rows). | R31: =IFERROR(INDEX('Ground Truth'!$G$2:$G$105,MATCH(A31,'Ground Truth'!$A$2:$A$105,0)),"") -> NO | S31: =IFERROR(INDEX('Ground Truth'!$H$2:$H$105,MATCH(A31,'Ground Truth'!$A$2:$A$105,0)),"") -> insufficient_data | T31: =IF(S31="","",--(S31=H31)) -> 1 | U31: =IF(R31="","","Compared with user-reviewed Ground Truth") -> Compared with user-reviewed Ground Truth | V31: =IF(R31="","",--(R31=G31)) -> 1 | W31: =IF(R31="","",IF(AND(R31="YES",G31="YES"),"TP",IF(AND(R31="NO",G31="NO"),"TN",IF(AND(R31="NO",G31="YES"),"FP",IF(AND(R31="YES",G31="NO"),"FN","CHECK"))))) -> TN
A32: 31 | B32: UCI | C32: SAMPLE_UCI_POR | D32: SAMPLE_UCI_POR_CLASS | E32: A-C01 | F32: Compare performance trajectories | G32: YES | H32: executable | J32: pass | K32: pass | L32: pass | M32: pass | P32: HIGH | Q32: 649 students × 3 assessments across 3 weeks - strong statistical basic | R32: =IFERROR(INDEX('Ground Truth'!$G$2:$G$105,MATCH(A32,'Ground Truth'!$A$2:$A$105,0)),"") -> YES | S32: =IFERROR(INDEX('Ground Truth'!$H$2:$H$105,MATCH(A32,'Ground Truth'!$A$2:$A$105,0)),"") -> executable | T32: =IF(S32="","",--(S32=H32)) -> 1 | U32: =IF(R32="","","Compared with user-reviewed Ground Truth") -> Compared with user-reviewed Ground Truth | V32: =IF(R32="","",--(R32=G32)) -> 1 | W32: =IF(R32="","",IF(AND(R32="YES",G32="YES"),"TP",IF(AND(R32="NO",G32="NO"),"TN",IF(AND(R32="NO",G32="YES"),"FP",IF(AND(R32="YES",G32="NO"),"FN","CHECK"))))) -> TP
A33: 32 | B33: UCI | C33: SAMPLE_UCI_POR | D33: SAMPLE_UCI_POR_CLASS | E33: A-C02 | F33: Compare engagement patterns | G33: NO | H33: insufficient_data | I33: Task depends on OULAD engagement/online activity signals. | J33: pass | K33: fail | L33: pass | M33: fail | N33: engagement_tracking | P33: LOW | Q33: No positive engagement activity found (0 engagement rows). | R33: =IFERROR(INDEX('Ground Truth'!$G$2:$G$105,MATCH(A33,'Ground Truth'!$A$2:$A$105,0)),"") -> NO | S33: =IFERROR(INDEX('Ground Truth'!$H$2:$H$105,MATCH(A33,'Ground Truth'!$A$2:$A$105,0)),"") -> insufficient_data | T33: =IF(S33="","",--(S33=H33)) -> 1 | U33: =IF(R33="","","Compared with user-reviewed Ground Truth") -> Compared with user-reviewed Ground Truth | V33: =IF(R33="","",--(R33=G33)) -> 1 | W33: =IF(R33="","",IF(AND(R33="YES",G33="YES"),"TP",IF(AND(R33="NO",G33="NO"),"TN",IF(AND(R33="NO",G33="YES"),"FP",IF(AND(R33="YES",G33="NO"),"FN","CHECK"))))) -> TN
A34: 33 | B34: UCI | C34: SAMPLE_UCI_POR | D34: SAMPLE_UCI_POR_CLASS | E34: A-C03 | F34: Compare risk profile | G34: NO | H34: insufficient_data | I34: Task depends on OULAD engagement/online activity signals. | J34: pass | K34: fail | L34: pass | M34: fail | N34: engagement_tracking | P34: LOW | Q34: No positive engagement activity found (0 engagement rows). | R34: =IFERROR(INDEX('Ground Truth'!$G$2:$G$105,MATCH(A34,'Ground Truth'!$A$2:$A$105,0)),"") -> NO | S34: =IFERROR(INDEX('Ground Truth'!$H$2:$H$105,MATCH(A34,'Ground Truth'!$A$2:$A$105,0)),"") -> insufficient_data | T34: =IF(S34="","",--(S34=H34)) -> 1 | U34: =IF(R34="","","Compared with user-reviewed Ground Truth") -> Compared with user-reviewed Ground Truth | V34: =IF(R34="","",--(R34=G34)) -> 1 | W34: =IF(R34="","",IF(AND(R34="YES",G34="YES"),"TP",IF(AND(R34="NO",G34="NO"),"TN",IF(AND(R34="NO",G34="YES"),"FP",IF(AND(R34="YES",G34="NO"),"FN","CHECK"))))) -> TN
A35: 34 | B35: UCI | C35: SAMPLE_UCI_POR | D35: SAMPLE_UCI_POR_CLASS | E35: A-C04 | F35: Compare lifestyle context | G35: YES | H35: executable | J35: pass | K35: pass | L35: pass | M35: pass | P35: HIGH | Q35: 649 students × 3 assessments across 3 weeks - strong statistical basic | R35: =IFERROR(INDEX('Ground Truth'!$G$2:$G$105,MATCH(A35,'Ground Truth'!$A$2:$A$105,0)),"") -> YES | S35: =IFERROR(INDEX('Ground Truth'!$H$2:$H$105,MATCH(A35,'Ground Truth'!$A$2:$A$105,0)),"") -> executable | T35: =IF(S35="","",--(S35=H35)) -> 1 | U35: =IF(R35="","","Compared with user-reviewed Ground Truth") -> Compared with user-reviewed Ground Truth | V35: =IF(R35="","",--(R35=G35)) -> 1 | W35: =IF(R35="","",IF(AND(R35="YES",G35="YES"),"TP",IF(AND(R35="NO",G35="NO"),"TN",IF(AND(R35="NO",G35="YES"),"FP",IF(AND(R35="YES",G35="NO"),"FN","CHECK"))))) -> TP
A36: 35 | B36: UCI | C36: SAMPLE_UCI_POR | D36: SAMPLE_UCI_POR_CLASS | E36: A-C05 | F36: Compare academic background | G36: YES | H36: executable | J36: pass | K36: pass | L36: pass | M36: pass | P36: HIGH | Q36: 649 students × 3 assessments across 3 weeks - strong statistical basic | R36: =IFERROR(INDEX('Ground Truth'!$G$2:$G$105,MATCH(A36,'Ground Truth'!$A$2:$A$105,0)),"") -> YES | S36: =IFERROR(INDEX('Ground Truth'!$H$2:$H$105,MATCH(A36,'Ground Truth'!$A$2:$A$105,0)),"") -> executable | T36: =IF(S36="","",--(S36=H36)) -> 1 | U36: =IF(R36="","","Compared with user-reviewed Ground Truth") -> Compared with user-reviewed Ground Truth | V36: =IF(R36="","",--(R36=G36)) -> 1 | W36: =IF(R36="","",IF(AND(R36="YES",G36="YES"),"TP",IF(AND(R36="NO",G36="NO"),"TN",IF(AND(R36="NO",G36="YES"),"FP",IF(AND(R36="YES",G36="NO"),"FN","CHECK"))))) -> TP
A37: 36 | B37: UCI | C37: SAMPLE_UCI_POR | D37: SAMPLE_UCI_POR_CLASS | E37: A-C06 | F37: Compare resource usage | G37: NO | H37: insufficient_data | I37: Required capability missing: engagement_tracking | J37: pass | K37: fail | L37: pass | M37: fail | N37: engagement_tracking; resource_clickstream | P37: LOW | Q37: No positive engagement activity found (0 engagement rows). | R37: =IFERROR(INDEX('Ground Truth'!$G$2:$G$105,MATCH(A37,'Ground Truth'!$A$2:$A$105,0)),"") -> NO | S37: =IFERROR(INDEX('Ground Truth'!$H$2:$H$105,MATCH(A37,'Ground Truth'!$A$2:$A$105,0)),"") -> insufficient_data | T37: =IF(S37="","",--(S37=H37)) -> 1 | U37: =IF(R37="","","Compared with user-reviewed Ground Truth") -> Compared with user-reviewed Ground Truth | V37: =IF(R37="","",--(R37=G37)) -> 1 | W37: =IF(R37="","",IF(AND(R37="YES",G37="YES"),"TP",IF(AND(R37="NO",G37="NO"),"TN",IF(AND(R37="NO",G37="YES"),"FP",IF(AND(R37="YES",G37="NO"),"FN","CHECK"))))) -> TN
A38: 37 | B38: UCI | C38: SAMPLE_UCI_POR | D38: SAMPLE_UCI_POR_CLASS | E38: A-G01 | F38: Identify low-engagement group | G38: NO | H38: insufficient_data | I38: Required capability missing: engagement_tracking | J38: pass | K38: fail | L38: pass | M38: fail | N38: engagement_tracking | P38: LOW | Q38: No positive engagement activity found (0 engagement rows). | R38: =IFERROR(INDEX('Ground Truth'!$G$2:$G$105,MATCH(A38,'Ground Truth'!$A$2:$A$105,0)),"") -> NO | S38: =IFERROR(INDEX('Ground Truth'!$H$2:$H$105,MATCH(A38,'Ground Truth'!$A$2:$A$105,0)),"") -> insufficient_data | T38: =IF(S38="","",--(S38=H38)) -> 1 | U38: =IF(R38="","","Compared with user-reviewed Ground Truth") -> Compared with user-reviewed Ground Truth | V38: =IF(R38="","",--(R38=G38)) -> 1 | W38: =IF(R38="","",IF(AND(R38="YES",G38="YES"),"TP",IF(AND(R38="NO",G38="NO"),"TN",IF(AND(R38="NO",G38="YES"),"FP",IF(AND(R38="YES",G38="NO"),"FN","CHECK"))))) -> TN
A39: 38 | B39: UCI | C39: SAMPLE_UCI_POR | D39: SAMPLE_UCI_POR_CLASS | E39: A-G02 | F39: Engagementâ€“performance relationship | G39: NO | H39: insufficient_data | I39: Task depends on OULAD engagement/online activity signals. | J39: pass | K39: fail | L39: pass | M39: fail | N39: engagement_tracking | P39: LOW | Q39: No positive engagement activity found (0 engagement rows). | R39: =IFERROR(INDEX('Ground Truth'!$G$2:$G$105,MATCH(A39,'Ground Truth'!$A$2:$A$105,0)),"") -> NO | S39: =IFERROR(INDEX('Ground Truth'!$H$2:$H$105,MATCH(A39,'Ground Truth'!$A$2:$A$105,0)),"") -> insufficient_data | T39: =IF(S39="","",--(S39=H39)) -> 1 | U39: =IF(R39="","","Compared with user-reviewed Ground Truth") -> Compared with user-reviewed Ground Truth | V39: =IF(R39="","",--(R39=G39)) -> 1 | W39: =IF(R39="","",IF(AND(R39="YES",G39="YES"),"TP",IF(AND(R39="NO",G39="NO"),"TN",IF(AND(R39="NO",G39="YES"),"FP",IF(AND(R39="YES",G39="NO"),"FN","CHECK"))))) -> TN
A40: 39 | B40: UCI | C40: SAMPLE_UCI_POR | D40: SAMPLE_UCI_POR_CLASS | E40: A-G03 | F40: Identify at-risk cohort | G40: YES | H40: executable | J40: pass | K40: pass | L40: pass | M40: pass | P40: HIGH | Q40: 649 students × 3 assessments across 3 weeks - strong statistical basic | R40: =IFERROR(INDEX('Ground Truth'!$G$2:$G$105,MATCH(A40,'Ground Truth'!$A$2:$A$105,0)),"") -> YES | S40: =IFERROR(INDEX('Ground Truth'!$H$2:$H$105,MATCH(A40,'Ground Truth'!$A$2:$A$105,0)),"") -> executable | T40: =IF(S40="","",--(S40=H40)) -> 1 | U40: =IF(R40="","","Compared with user-reviewed Ground Truth") -> Compared with user-reviewed Ground Truth | V40: =IF(R40="","",--(R40=G40)) -> 1 | W40: =IF(R40="","",IF(AND(R40="YES",G40="YES"),"TP",IF(AND(R40="NO",G40="NO"),"TN",IF(AND(R40="NO",G40="YES"),"FP",IF(AND(R40="YES",G40="NO"),"FN","CHECK"))))) -> TP
...

Sheet Capability Check
A1: dataset | B1: batch_id | C1: class_id | D1: capability | E1: available | F1: evidence_metric | G1: evidence_value | H1: threshold_or_rule | I1: groundtruth_note | K1: Dataset Metric Snapshot
A2: UCI | B2: SAMPLE_UCI_POR | C2: SAMPLE_UCI_POR_CLASS | D2: absence_tracking | E2: YES | F2: absences_non_null_rows | G2: 649 | H2: >= 1 absence row | I2: Available in dataset snapshot | K2: dataset | L2: metric | M2: value | N2: note
A3: UCI | B3: SAMPLE_UCI_POR | C3: SAMPLE_UCI_POR_CLASS | D3: assessment_scores | E3: YES | F3: score_non_null_rows | G3: 1947 | H3: >= 2 score rows | I3: Available in dataset snapshot | K3: UCI | L3: enrollment_rows | M3: 649 | N3: Used as evidence for capability inference
A4: UCI | B4: SAMPLE_UCI_POR | C4: SAMPLE_UCI_POR_CLASS | D4: competency_tagging | E4: NO | F4: competency_tag_non_null_rows | G4: 0 | H4: >= 1 native competency tag | I4: Unavailable / insufficient in dataset snapshot | K4: UCI | L4: distinct_students | M4: 649 | N4: Used as evidence for capability inference
A5: UCI | B5: SAMPLE_UCI_POR | C5: SAMPLE_UCI_POR_CLASS | D5: demographics | E5: YES | F5: demographics_students | G5: 649 | H5: >= 1 student with demographic fields | I5: Available in dataset snapshot | K5: UCI | L5: assessment_rows | M5: 3 | N5: Used as evidence for capability inference
A6: UCI | B6: SAMPLE_UCI_POR | C6: SAMPLE_UCI_POR_CLASS | D6: disadvantage_scoring | E6: NO | F6: disadvantage_score_students | G6: 0 | H6: disadvantage_score_students >= 2 | I6: Unavailable / insufficient in dataset snapshot | K6: UCI | L6: assessment_result_rows | M6: 1947 | N6: Used as evidence for capability inference
A7: UCI | B7: SAMPLE_UCI_POR | C7: SAMPLE_UCI_POR_CLASS | D7: engagement_tracking | E7: NO | F7: positive_engagement_rows | G7: 0 | H7: >= 1 positive engagement row | I7: Unavailable / insufficient in dataset snapshot | K7: UCI | L7: score_non_null_rows | M7: 1947 | N7: Used as evidence for capability inference
A8: UCI | B8: SAMPLE_UCI_POR | C8: SAMPLE_UCI_POR_CLASS | D8: family_context | E8: YES | F8: family_students | G8: 649 | H8: >= 1 student with family-context fields | I8: Available in dataset snapshot | K8: UCI | L8: final_outcome_non_null_rows | M8: 649 | N8: Used as evidence for capability inference
A9: UCI | B9: SAMPLE_UCI_POR | C9: SAMPLE_UCI_POR_CLASS | D9: final_outcome | E9: YES | F9: final_outcome_non_null_rows | G9: 649 | H9: >= 1 outcome row | I9: Available in dataset snapshot | K9: UCI | L9: submission_day_non_null_rows | M9: 0 | N9: Used as evidence for capability inference
A10: UCI | B10: SAMPLE_UCI_POR | C10: SAMPLE_UCI_POR_CLASS | D10: lifestyle_factors | E10: YES | F10: lifestyle_students | G10: 649 | H10: >= 1 student with lifestyle fields | I10: Available in dataset snapshot | K10: UCI | L10: engagement_rows | M10: 0 | N10: Used as evidence for capability inference
A11: UCI | B11: SAMPLE_UCI_POR | C11: SAMPLE_UCI_POR_CLASS | D11: multi_student_comparison | E11: YES | F11: distinct_students | G11: 649 | H11: >= 2 students | I11: Available in dataset snapshot | K11: UCI | L11: positive_engagement_rows | M11: 0 | N11: Used as evidence for capability inference
A12: UCI | B12: SAMPLE_UCI_POR | C12: SAMPLE_UCI_POR_CLASS | D12: proxy_competency_available | E12: YES | F12: assessment_name_non_null_rows | G12: 3 | H12: >= 1 assessment name usable as proxy | I12: Available in dataset snapshot | K12: UCI | L12: distinct_engagement_weeks | M12: 0 | N12: Used as evidence for capability inference
A13: UCI | B13: SAMPLE_UCI_POR | C13: SAMPLE_UCI_POR_CLASS | D13: registration_timing | E13: NO | F13: registration_non_null_rows | G13: 0 | H13: >= 1 registration timing row | I13: Unavailable / insufficient in dataset snapshot | K13: UCI | L13: resource_type_non_null_rows | M13: 0 | N13: Used as evidence for capability inference
A14: UCI | B14: SAMPLE_UCI_POR | C14: SAMPLE_UCI_POR_CLASS | D14: resource_clickstream | E14: NO | F14: resource_type_non_null_rows | G14: 0 | H14: positive_engagement_rows >= 1 AND resource_type_non_null_rows >= 1 | I14: Unavailable / insufficient in dataset snapshot | K14: UCI | L14: absences_non_null_rows | M14: 649 | N14: Used as evidence for capability inference
... A17: UCI | B17: SAMPLE_UCI_POR | C17: SAMPLE_UCI_POR_CLASS | D17: submission_history | E17: YES | F17: assessment_result_rows | G17: 1947 | H17: >= 1 assessment result row | I17: Available in dataset snapshot | K17: UCI | L17: family_students | M17: 649 | N17: Used as evidence for capability inference
A18: UCI | B18: SAMPLE_UCI_POR | C18: SAMPLE_UCI_POR_CLASS | D18: submission_timestamps | E18: NO | F18: submission_day_non_null_rows + due_day_non_null_rows | G18: submission_day=0, due_day=3 | H18: both > 0 | I18: Unavailable / insufficient in dataset snapshot | K18: UCI | L18: socioeconomic_students | M18: 0 | N18: Used as evidence for capability inference
A19: UCI | B19: SAMPLE_UCI_POR | C19: SAMPLE_UCI_POR_CLASS | D19: temporal_activity | E19: NO | F19: distinct_engagement_weeks / distinct_engagement_days | G19: weeks=0, days=0 | H19: positive_engagement_rows >= 1 AND distinct_engagement_weeks >= 2 | I19: Unavailable / insufficient in dataset snapshot | K19: UCI | L19: disadvantage_score_students | M19: 0 | N19: Used as evidence for capability inference
A20: OULAD | B20: SAMPLE_OULAD | C20: SAMPLE_OULAD_CLASS_CCC_2014J | D20: absence_tracking | E20: NO | F20: absences_non_null_rows | G20: 0 | H20: >= 1 absence row | I20: Unavailable / insufficient in dataset snapshot | K20: UCI | L20: registration_non_null_rows | M20: 0 | N20: Used as evidence for capability inference
A21: OULAD | B21: SAMPLE_OULAD | C21: SAMPLE_OULAD_CLASS_CCC_2014J | D21: assessment_scores | E21: YES | F21: score_non_null_rows | G21: 11445 | H21: >= 2 score rows | I21: Available in dataset snapshot | K21: OULAD | L21: enrollment_rows | M21: 2498 | N21: Used as evidence for capability inference
A22: OULAD | B22: SAMPLE_OULAD | C22: SAMPLE_OULAD_CLASS_CCC_2014J | D22: competency_tagging | E22: NO | F22: competency_tag_non_null_rows | G22: 0 | H22: >= 1 native competency tag | I22: Unavailable / insufficient in dataset snapshot | K22: OULAD | L22: distinct_students | M22: 2498 | N22: Used as evidence for capability inference
A23: OULAD | B23: SAMPLE_OULAD | C23: SAMPLE_OULAD_CLASS_CCC_2014J | D23: demographics | E23: YES | F23: demographics_students | G23: 2498 | H23: >= 1 student with demographic fields | I23: Available in dataset snapshot | K23: OULAD | L23: assessment_rows | M23: 10 | N23: Used as evidence for capability inference
A24: OULAD | B24: SAMPLE_OULAD | C24: SAMPLE_OULAD_CLASS_CCC_2014J | D24: disadvantage_scoring | E24: YES | F24: disadvantage_score_students | G24: 2360 | H24: disadvantage_score_students >= 2 | I24: Available in dataset snapshot | K24: OULAD | L24: assessment_result_rows | M24: 11451 | N24: Used as evidence for capability inference
A25: OULAD | B25: SAMPLE_OULAD | C25: SAMPLE_OULAD_CLASS_CCC_2014J | D25: engagement_tracking | E25: YES | F25: positive_engagement_rows | G25: 515832 | H25: >= 1 positive engagement row | I25: Available in dataset snapshot | K25: OULAD | L25: score_non_null_rows | M25: 11445 | N25: Used as evidence for capability inference
A26: OULAD | B26: SAMPLE_OULAD | C26: SAMPLE_OULAD_CLASS_CCC_2014J | D26: family_context | E26: NO | F26: family_students | G26: 0 | H26: >= 1 student with family-context fields | I26: Unavailable / insufficient in dataset snapshot | K26: OULAD | L26: final_outcome_non_null_rows | M26: 2498 | N26: Used as evidence for capability inference
A27: OULAD | B27: SAMPLE_OULAD | C27: SAMPLE_OULAD_CLASS_CCC_2014J | D27: final_outcome | E27: YES | F27: final_outcome_non_null_rows | G27: 2498 | H27: >= 1 outcome row | I27: Available in dataset snapshot | K27: OULAD | L27: submission_day_non_null_rows | M27: 11451 | N27: Used as evidence for capability inference
A28: OULAD | B28: SAMPLE_OULAD | C28: SAMPLE_OULAD_CLASS_CCC_2014J | D28: lifestyle_factors | E28: NO | F28: lifestyle_students | G28: 0 | H28: >= 1 student with lifestyle fields | I28: Unavailable / insufficient in dataset snapshot | K28: OULAD | L28: engagement_rows | M28: 515832 | N28: Used as evidence for capability inference
A29: OULAD | B29: SAMPLE_OULAD | C29: SAMPLE_OULAD_CLASS_CCC_2014J | D29: multi_student_comparison | E29: YES | F29: distinct_students | G29: 2498 | H29: >= 2 students | I29: Available in dataset snapshot | K29: OULAD | L29: positive_engagement_rows | M29: 515832 | N29: Used as evidence for capability inference
A30: OULAD | B30: SAMPLE_OULAD | C30: SAMPLE_OULAD_CLASS_CCC_2014J | D30: proxy_competency_available | E30: YES | F30: assessment_name_non_null_rows | G30: 10 | H30: >= 1 assessment name usable as proxy | I30: Available in dataset snapshot | K30: OULAD | L30: distinct_engagement_weeks | M30: 42 | N30: Used as evidence for capability inference
A31: OULAD | B31: SAMPLE_OULAD | C31: SAMPLE_OULAD_CLASS_CCC_2014J | D31: registration_timing | E31: YES | F31: registration_non_null_rows | G31: 2482 | H31: >= 1 registration timing row | I31: Available in dataset snapshot | K31: OULAD | L31: resource_type_non_null_rows | M31: 223 | N31: Used as evidence for capability inference
... A35: OULAD | B35: SAMPLE_OULAD | C35: SAMPLE_OULAD_CLASS_CCC_2014J | D35: submission_history | E35: YES | F35: assessment_result_rows | G35: 11451 | H35: >= 1 assessment result row | I35: Available in dataset snapshot | K35: OULAD | L35: family_students | M35: 0 | N35: Used as evidence for capability inference
A36: OULAD | B36: SAMPLE_OULAD | C36: SAMPLE_OULAD_CLASS_CCC_2014J | D36: submission_timestamps | E36: YES | F36: submission_day_non_null_rows + due_day_non_null_rows | G36: submission_day=11451, due_day=8 | H36: both > 0 | I36: Available in dataset snapshot | K36: OULAD | L36: socioeconomic_students | M36: 2498 | N36: Used as evidence for capability inference
A37: OULAD | B37: SAMPLE_OULAD | C37: SAMPLE_OULAD_CLASS_CCC_2014J | D37: temporal_activity | E37: YES | F37: distinct_engagement_weeks / distinct_engagement_days | G37: weeks=42, days=288 | H37: positive_engagement_rows >= 1 AND distinct_engagement_weeks >= 2 | I37: Available in dataset snapshot | K37: OULAD | L37: disadvantage_score_students | M37: 2360 | N37: Used as evidence for capability inference
K38: OULAD | L38: registration_non_null_rows | M38: 2482 | N38: Used as evidence for capability inference

Sheet Evaluation Summary
A1: Task Availability Validator Evaluation Summary
A2: All metrics are Excel formulas calculated from Machine Results, which is formula-linked to the user-reviewed Ground Truth sheet.
A4: Metric | B4: Formula result | C4: Formula definition
A5: Total cases | B5: =COUNTA('Machine Results'!A2:A105) -> 104 | C5: Number of task x dataset pairs
A6: TP | B6: =COUNTIF('Machine Results'!W2:W105,"TP") -> 68 | C6: Gold YES and machine YES
A7: TN | B7: =COUNTIF('Machine Results'!W2:W105,"TN") -> 36 | C7: Gold NO and machine NO
A8: FP | B8: =COUNTIF('Machine Results'!W2:W105,"FP") -> 0 | C8: Gold NO but machine YES
A9: FN | B9: =COUNTIF('Machine Results'!W2:W105,"FN") -> 0 | C9: Gold YES but machine NO
A10: Accuracy | B10: =IF(B5=0,"",(B6+B7)/B5) -> 1 | C10: (TP + TN) / Total
A11: Precision | B11: =IF((B6+B8)=0,"",B6/(B6+B8)) -> 1 | C11: TP / (TP + FP)
A12: Recall | B12: =IF((B6+B9)=0,"",B6/(B6+B9)) -> 1 | C12: TP / (TP + FN)
A13: F1-score | B13: =IF((B11+B12)=0,"",2*B11*B12/(B11+B12)) -> 1 | C13: 2 x Precision x Recall / (Precision + Recall)
A14: Exact status correct | B14: =COUNTIF('Machine Results'!T2:T105,1) -> 104 | C14: Expected status exactly equals machine status
A15: Exact status accuracy | B15: =IF(B5=0,"",B14/B5) -> 1 | C15: Exact status correct / Total
A18: Machine status by dataset
A19: Dataset | B19: Total | C19: Executable | D19: Partial | E19: Insufficient data | F19: Unsupported
A20: UCI | B20: =COUNTIF('Machine Results'!B:B,A20) -> 52 | C20: =COUNTIFS('Machine Results'!B:B,A20,'Machine Results'!H:H,"executable") -> 24 | D20: =COUNTIFS('Machine Results'!B:B,A20,'Machine Results'!H:H,"partial") -> 6 | E20: =COUNTIFS('Machine Results'!B:B,A20,'Machine Results'!H:H,"insufficient_data") -> 22 | F20: =COUNTIFS('Machine Results'!B:B,A20,'Machine Results'!H:H,"unsupported") -> 0
A21: OULAD | B21: =COUNTIF('Machine Results'!B:B,A21) -> 52 | C21: =COUNTIFS('Machine Results'!B:B,A21,'Machine Results'!H:H,"executable") -> 44 | D21: =COUNTIFS('Machine Results'!B:B,A21,'Machine Results'!H:H,"partial") -> 8 | E21: =COUNTIFS('Machine Results'!B:B,A21,'Machine Results'!H:H,"insufficient_data") -> 0 | F21: =COUNTIFS('Machine Results'!B:B,A21,'Machine Results'!H:H,"unsupported") -> 0

Sheet README
A1: Item | B1: Description
A2: Purpose | B2: This workbook evaluates Task Availability Validator accuracy using machine-generated logs and manual ground truth labels.
A3: Machine Results | B3: Automatic validator output plus independent gold labels and TP/TN/FP/FN comparison.
A4: Ground Truth | B4: Independent labels derived only from [Final] Analysis_tasks (2).xlsx Dataset Compatibility; contains no machine fields.
A5: Availability rule | B5: machine_available = YES only when machine_status is executable; partial/insufficient_data/unsupported are treated as NO for clean downstream AI evaluation.
A6: Error types | B6: TP: both YES; TN: both NO; FP: machine lets invalid task pass; FN: machine blocks valid task.
A7: Source logs | B7: task_availability_20260619T042411Z_265c90.json and task_availability_20260619T042455Z_0ef6b3.json
A8: Capability Check | B8: Supporting evidence sheet showing dataset-level capabilities, runtime metrics, and the exact boolean thresholds used by the validator.
A9: Expected status | B9: Derived independently from Dataset Compatibility: compatible task-dataset pair -> executable; incompatible pair -> unsupported. Binary and exact-status accuracy are reported separately.
A10: Recalculation | B10: Machine Results comparison columns and Evaluation Summary were recalculated from the user-reviewed Ground Truth on 2026-06-19.
